Workbook

Sheet Main_260211
A1: Class+Node [(Identifier (Key)] | B1: Class [Not chosen] | C1: Node [Not chosen] | D1: Required Mods [Not chosen] | E1: English [Source string] | F1: Korean (한국어) [Translation]
A2: AbilityDef+VFEP_FiringFrenzy.label | B2: AbilityDef | C2: VFEP_FiringFrenzy.label | E2: firing frenzy | F2: 사격 열광
A3: AbilityDef+VFEP_FiringFrenzy.description | B3: AbilityDef | C3: VFEP_FiringFrenzy.description | E3: Inspire everyone nearby to increase their firing rate and withstand greater amounts of pain. The effect remains attached to the caster for 24 hours. | F3: 주변의 모든 이들에게 사격 속도를 증가시키고, 더 큰 고통을 견딜 수 있는 용기를 불어넣습니다. 효과는 24시간 동안 유지됩니다.
A4: AbilityDef+VWEB_WarbolterLongBurner.label | B4: AbilityDef | C4: VWEB_WarbolterLongBurner.label | E4: warbolter long burner | F4: 워볼터 화염방사기
A5: AbilityDef+VWEB_WarbolterLongBurner.description | B5: AbilityDef | C5: VWEB_WarbolterLongBurner.description | E5: Fire a short-ranged flame blast over a short but wide area. | F5: 매우 먼 거리까지 화염을 발사합니다.
A6: BodyDef+VFEP_Wardrone.corePart.parts.0.parts.0.parts.1.customLabel | B6: BodyDef | C6: VFEP_Wardrone.corePart.parts.0.parts.0.parts.1.customLabel | E6: left sight sensor | F6: 왼쪽 시각 센서
A7: BodyDef+VFEP_Wardrone.corePart.parts.0.parts.0.parts.2.customLabel | B7: BodyDef | C7: VFEP_Wardrone.corePart.parts.0.parts.0.parts.2.customLabel | E7: right sight sensor | F7: 오른쪽 시각 센서
A8: BodyDef+VFEP_Wardrone.corePart.parts.0.parts.0.parts.3.customLabel | B8: BodyDef | C8: VFEP_Wardrone.corePart.parts.0.parts.0.parts.3.customLabel | E8: left hearing sensor | F8: 왼쪽 청각 센서
A9: BodyDef+VFEP_Wardrone.corePart.parts.0.parts.0.parts.4.customLabel | B9: BodyDef | C9: VFEP_Wardrone.corePart.parts.0.parts.0.parts.4.customLabel | E9: right hearing sensor | F9: 오른쪽 청각 센서
A10: BodyDef+VFEP_Wardrone.corePart.parts.1.customLabel | B10: BodyDef | C10: VFEP_Wardrone.corePart.parts.1.customLabel | E10: left propeller | F10: 왼쪽 추진기
A11: BodyDef+VFEP_Wardrone.corePart.parts.2.customLabel | B11: BodyDef | C11: VFEP_Wardrone.corePart.parts.2.customLabel | E11: right propeller | F11: 오른쪽 추진기
A12: BodyDef+VFEP_Spidermine.corePart.parts.0.parts.0.parts.1.customLabel | B12: BodyDef | C12: VFEP_Spidermine.corePart.parts.0.parts.0.parts.1.customLabel | E12: left sight sensor | F12: 왼쪽 시각 센서
A13: BodyDef+VFEP_Spidermine.corePart.parts.0.parts.0.parts.2.customLabel | B13: BodyDef | C13: VFEP_Spidermine.corePart.parts.0.parts.0.parts.2.customLabel | E13: right sight sensor | F13: 오른쪽 시각 센서
... A1116: Strings+Names.Junker_Last.100 | B1116: Strings | C1116: Names.Junker_Last.100 | E1116: Zealous | F1116: 질러스

Sheet Old
A1: Class+Node [(Identifier (Key)] | B1: Class [Not chosen] | C1: Node [Not chosen] | D1: EN [Source string] | E1: KO [Translation] | F1: Configs [Not chosen] | G1: Rimgaller1 [Not chosen]
A2: VFECore.Abilities.AbilityDef+VFEP_GrapplingHook.label | B2: VFECore.Abilities.AbilityDef | C2: VFEP_GrapplingHook.label | D2: grappling hook | E2: 그래플링 훅 | F2: pakageID | G2: {=_xlfn.lambda(_xlpm.x,IFERROR(_xlpm.x,""))(VLOOKUP(A2,Merge!$A$122:$B$797,2,FALSE()))} -> #VALUE!
A3: VFECore.Abilities.AbilityDef+VFEP_GrapplingHook.jobReportString | B3: VFECore.Abilities.AbilityDef | C3: VFEP_GrapplingHook.jobReportString | E3: 그래플링 훅 사용 중 | F3: OskarPotocki.VFE.Pirates
A4: VFECore.Abilities.AbilityDef+VFEP_GrapplingHook.description | B4: VFECore.Abilities.AbilityDef | C4: VFEP_GrapplingHook.description | D4: Grappling hook connects to walls and solid rock and allows the users to quickly move to the desired location. The launcher does not require ammunition, but time needs to be reserved between shots to wind it up again. | E4: 갈고리 사슬을 벽에 고정시켜 사용자가 원하는 위치로 빠르게 이동할 수 있게 해줍니다. 사용에 별도의 준비가 필요하진 않으나, 재차 사용하려면 연결된 사슬을 다시 감아올릴 시간이 필요합니다. | F4: modName (folderName) | G4: {=_xlfn.lambda(_xlpm.x,IFERROR(_xlpm.x,""))(VLOOKUP(A4,Merge!$A$122:$B$797,2,FALSE()))} -> #VALUE!
A5: VFECore.Abilities.AbilityDef+VFEP_SiegeMode.label | B5: VFECore.Abilities.AbilityDef | C5: VFEP_SiegeMode.label | D5: Siege Mode | E5: 공성 모드 | F5: Vanilla Factions Expanded - Pirates - 2723801948 | G5: {=_xlfn.lambda(_xlpm.x,IFERROR(_xlpm.x,""))(VLOOKUP(A5,Merge!$A$122:$B$797,2,FALSE()))} -> #VALUE!
A6: VFECore.Abilities.AbilityDef+VFEP_SiegeMode.jobReportString | B6: VFECore.Abilities.AbilityDef | C6: VFEP_SiegeMode.jobReportString | E6: 공성 모드 사용 중
A7: VFECore.Abilities.AbilityDef+VFEP_SiegeMode.description | B7: VFECore.Abilities.AbilityDef | C7: VFEP_SiegeMode.description | D7: Drill yourself into the ground in order to gain more stability and turn yourself into a stationary artillery unit, increasing the attack range and reload efficiency drastically. | E7: 사격 안정성을 높이기 위해 지면에 다리를 박고 고정 포대가 되어 사거리를 늘이고 재사용 대기시간을 줄입니다.\n\n제자리에서 벗어나면 자동으로 해제됩니다. | G7: {=_xlfn.lambda(_xlpm.x,IFERROR(_xlpm.x,""))(VLOOKUP(A7,Merge!$A$122:$B$797,2,FALSE()))} -> #VALUE!
A8: VFECore.Abilities.AbilityDef+VFEP_PowerJump.label | B8: VFECore.Abilities.AbilityDef | C8: VFEP_PowerJump.label | D8: Power jump | E8: 충격 도약 | G8: {=_xlfn.lambda(_xlpm.x,IFERROR(_xlpm.x,""))(VLOOKUP(A8,Merge!$A$122:$B$797,2,FALSE()))} -> #VALUE!
A9: VFECore.Abilities.AbilityDef+VFEP_PowerJump.jobReportString | B9: VFECore.Abilities.AbilityDef | C9: VFEP_PowerJump.jobReportString | E9: 충격 도약 사용 중
A10: VFECore.Abilities.AbilityDef+VFEP_PowerJump.description | B10: VFECore.Abilities.AbilityDef | C10: VFEP_PowerJump.description | D10: Use shoulder-mounted jump packs to travel a short distance and create a small explosion at both start and end of the flight. | E10: 어깨에 달린 점프팩을 사용해 짧은 거리를 뛰어오릅니다. 도약과 착지 순간 주변에 작은 폭발을 일으킵니다. | G10: {=_xlfn.lambda(_xlpm.x,IFERROR(_xlpm.x,""))(VLOOKUP(A10,Merge!$A$122:$B$797,2,FALSE()))} -> #VALUE!
A11: VFECore.Abilities.AbilityDef+VFEP_BlastOff.label | B11: VFECore.Abilities.AbilityDef | C11: VFEP_BlastOff.label | D11: Blast off | E11: 강습 비행 | G11: {=_xlfn.lambda(_xlpm.x,IFERROR(_xlpm.x,""))(VLOOKUP(A11,Merge!$A$122:$B$797,2,FALSE()))} -> #VALUE!
A12: VFECore.Abilities.AbilityDef+VFEP_BlastOff.jobReportString | B12: VFECore.Abilities.AbilityDef | C12: VFEP_BlastOff.jobReportString | E12: 강습 비행 사용 중
A13: VFECore.Abilities.AbilityDef+VFEP_BlastOff.description | B13: VFECore.Abilities.AbilityDef | C13: VFEP_BlastOff.description | D13: Fire a large propulsion engine strapped to the back of your armor and designate a location on the world map to drop pod into. This will create a large explosion at the destination, but will most likely leave you stranded without fuel for the trip back. | E13: 등에 달린 추력 엔진을 사용하여 하늘로 날아올라, 세계 지도에서 지정한 지역에 커다란 폭발을 일으키며 착지합니다. 경로 계산 시스템이 정밀하지 않아서 착지 지점은 맵 중앙으로 고정됩니다.\n\n비행 중에 모든 연료를 써버리기 때문에, 계획을 잘 세우지 않으면 고립되고 말 것입니다. | G13: {=_xlfn.lambda(_xlpm.x,IFERROR(_xlpm.x,""))(VLOOKUP(A13,Merge!$A$122:$B$797,2,FALSE()))} -> #VALUE!
A14: ThingDef+VFEP_Bullet_GrapplingHook.label | B14: ThingDef | C14: VFEP_Bullet_GrapplingHook.label | D14: grappling hook | E14: 갈고리 | G14: {=_xlfn.lambda(_xlpm.x,IFERROR(_xlpm.x,""))(VLOOKUP(A14,Merge!$A$122:$B$797,2,FALSE()))} -> #VALUE!
A15: ThingDef+VFEP_ActiveDropPawn.label | B15: ThingDef | C15: VFEP_ActiveDropPawn.label | D15: drop pawn | G15: {=_xlfn.lambda(_xlpm.x,IFERROR(_xlpm.x,""))(VLOOKUP(A15,Merge!$A$122:$B$797,2,FALSE()))} -> #VALUE!
A16: ThingDef+VFEP_Bullet_GauntletChargeCanon.label | B16: ThingDef | C16: VFEP_Bullet_GauntletChargeCanon.label | D16: gauntlet charge cannon bullet | E16: 펄스 충전 탄환 | G16: {=_xlfn.lambda(_xlpm.x,IFERROR(_xlpm.x,""))(VLOOKUP(A16,Merge!$A$122:$B$797,2,FALSE()))} -> #VALUE!
A17: ThingDef+VFEP_GauntletChargeCanon.label | B17: ThingDef | C17: VFEP_GauntletChargeCanon.label | D17: gauntlet charge cannon | E17: 건틀렛 차지 캐논 | G17: {=_xlfn.lambda(_xlpm.x,IFERROR(_xlpm.x,""))(VLOOKUP(A17,Merge!$A$122:$B$797,2,FALSE()))} -> #VALUE!
A18: ThingDef+VFEP_GauntletChargeCanon.description | B18: ThingDef | C18: VFEP_GauntletChargeCanon.description | D18: Ship mounted anti-armor charge cannon, often utilised in ship-to-ship combat in low atmosphere. | E18: 저궤도 전투함에서 주로 쓰이는 고정형 대장갑 차지 캐논입니다. | G18: {=_xlfn.lambda(_xlpm.x,IFERROR(_xlpm.x,""))(VLOOKUP(A18,Merge!$A$122:$B$797,2,FALSE()))} -> #VALUE!
A19: ThingDef+VFEP_CrashedShip_Black.label | B19: ThingDef | C19: VFEP_CrashedShip_Black.label | D19: crashed ship | E19: 추락한 건틀렛 함선 | G19: {=_xlfn.lambda(_xlpm.x,IFERROR(_xlpm.x,""))(VLOOKUP(A19,Merge!$A$122:$B$797,2,FALSE()))} -> #VALUE!
A20: ThingDef+VFEP_CrashedShip_Black.description | B20: ThingDef | C20: VFEP_CrashedShip_Black.description | D20: The Gauntlet combat-grade spacecraft is a ship-launched fighter cleared for low atmosphere operations. It was designed to strafe targets and take out enemy air units, however it fell out of favour due to numerous shortcomings and can frequently be found as part of military surplus.\n\nIt was not intended to land planetside as it doesn’t even have landing gear, but some enterprising individuals have decided to do just that. The mounted charge cannon works perfectly well against armored targets and the interior has been retrofitted to accommodate raid parties and supplies. The extra weight all but guarantees that the ship will be non-recoverable and create massive chaos when it flops onto the surface. | E20: 건틀렛 전투함은 모선에서 발진하여 대기권 저층에서의 작전을 수행하도록 설계되었습니다. 지상에 화력을 지원하거나 공중전에 쓰이도록 만들어졌지만, 각종 결함으로 인해 군의 관심을 잃게 되어 민간에 헐값으로 불하되는 신세가 되었습니다.\n\n우주에 가까운 높은 고도에서 활용할 목적이었기 때문에 지상 착륙을 위한 기어조차 달리지 않았지만, 몇몇 '진취적인' 사람들에겐 그러지 않을 이유가 되지 못했습니다. 어쨌든 장착된 차지 캐논은 중장갑에 아주 탁월했기 때문에, 습격조와 보급품을 실을 수 있도록 내부를 개조했습니다. 이렇게 늘어난 무게는 상승력을 떨어뜨려 추락하는 것 말고는 할 수 없게 되었으며, 지면에 충돌하며 엄청난 혼돈을 일으킬 것을 확실하게 보장해 줍니다. | G20: {=_xlfn.lambda(_xlpm.x,IFERROR(_xlpm.x,""))(VLOOKUP(A20,Merge!$A$122:$B$797,2,FALSE()))} -> #VALUE!
A21: ThingDef+VFEP_CrashedShip_Green.label | B21: ThingDef | C21: VFEP_CrashedShip_Green.label | D21: crashed ship | E21: 추락한 건틀렛 함선 | G21: {=_xlfn.lambda(_xlpm.x,IFERROR(_xlpm.x,""))(VLOOKUP(A21,Merge!$A$122:$B$797,2,FALSE()))} -> #VALUE!
A22: ThingDef+VFEP_CrashedShip_Green.description | B22: ThingDef | C22: VFEP_CrashedShip_Green.description | D22: The Gauntlet combat-grade spacecraft is a ship-launched fighter cleared for low atmosphere operations. It was designed to strafe targets and take out enemy air units, however it fell out of favour due to numerous shortcomings and can frequently be found as part of military surplus.\n\nIt was not intended to land planetside as it doesn’t even have landing gear, but some enterprising individuals have decided to do just that. The mounted charge cannon works perfectly well against armored targets and the interior has been retrofitted to accommodate raid parties and supplies. The extra weight all but guarantees that the ship will be non-recoverable and create massive chaos when it flops onto the surface. | E22: 건틀렛 전투함은 모선에서 발진하여 대기권 저층에서의 작전을 수행하도록 설계되었습니다. 지상에 화력을 지원하거나 공중전에 쓰이도록 만들어졌지만, 각종 결함으로 인해 군의 관심을 잃게 되어 민간에 헐값으로 불하되는 신세가 되었습니다.\n\n우주에 가까운 높은 고도에서 활용할 목적이었기 때문에 지상 착륙을 위한 기어조차 달리지 않았지만, 몇몇 '진취적인' 사람들에겐 그러지 않을 이유가 되지 못했습니다. 어쨌든 장착된 차지 캐논은 중장갑에 아주 탁월했기 때문에, 습격조와 보급품을 실을 수 있도록 내부를 개조했습니다. 이렇게 늘어난 무게는 상승력을 떨어뜨려 추락하는 것 말고는 할 수 없게 되었으며, 지면에 충돌하며 엄청난 혼돈을 일으킬 것을 확실하게 보장해 줍니다. | G22: {=_xlfn.lambda(_xlpm.x,IFERROR(_xlpm.x,""))(VLOOKUP(A22,Merge!$A$122:$B$797,2,FALSE()))} -> #VALUE!
A23: ThingDef+VFEP_CrashedShip_Orange.label | B23: ThingDef | C23: VFEP_CrashedShip_Orange.label | D23: crashed ship | E23: 추락한 건틀렛 함선 | G23: {=_xlfn.lambda(_xlpm.x,IFERROR(_xlpm.x,""))(VLOOKUP(A23,Merge!$A$122:$B$797,2,FALSE()))} -> #VALUE!
A24: ThingDef+VFEP_CrashedShip_Orange.description | B24: ThingDef | C24: VFEP_CrashedShip_Orange.description | D24: The Gauntlet combat-grade spacecraft is a ship-launched fighter cleared for low atmosphere operations. It was designed to strafe targets and take out enemy air units, however it fell out of favour due to numerous shortcomings and can frequently be found as part of military surplus.\n\nIt was not intended to land planetside as it doesn’t even have landing gear, but some enterprising individuals have decided to do just that. The mounted charge cannon works perfectly well against armored targets and the interior has been retrofitted to accommodate raid parties and supplies. The extra weight all but guarantees that the ship will be non-recoverable and create massive chaos when it flops onto the surface. | E24: 건틀렛 전투함은 모선에서 발진하여 대기권 저층에서의 작전을 수행하도록 설계되었습니다. 지상에 화력을 지원하거나 공중전에 쓰이도록 만들어졌지만, 각종 결함으로 인해 군의 관심을 잃게 되어 민간에 헐값으로 불하되는 신세가 되었습니다.\n\n우주에 가까운 높은 고도에서 활용할 목적이었기 때문에 지상 착륙을 위한 기어조차 달리지 않았지만, 몇몇 '진취적인' 사람들에겐 그러지 않을 이유가 되지 못했습니다. 어쨌든 장착된 차지 캐논은 중장갑에 아주 탁월했기 때문에, 습격조와 보급품을 실을 수 있도록 내부를 개조했습니다. 이렇게 늘어난 무게는 상승력을 떨어뜨려 추락하는 것 말고는 할 수 없게 되었으며, 지면에 충돌하며 엄청난 혼돈을 일으킬 것을 확실하게 보장해 줍니다. | G24: {=_xlfn.lambda(_xlpm.x,IFERROR(_xlpm.x,""))(VLOOKUP(A24,Merge!$A$122:$B$797,2,FALSE()))} -> #VALUE!
A25: ThingDef+VFEP_CrashedShip_Red.label | B25: ThingDef | C25: VFEP_CrashedShip_Red.label | D25: crashed ship | E25: 추락한 건틀렛 함선 | G25: {=_xlfn.lambda(_xlpm.x,IFERROR(_xlpm.x,""))(VLOOKUP(A25,Merge!$A$122:$B$797,2,FALSE()))} -> #VALUE!
A26: ThingDef+VFEP_CrashedShip_Red.description | B26: ThingDef | C26: VFEP_CrashedShip_Red.description | D26: The Gauntlet combat-grade spacecraft is a ship-launched fighter cleared for low atmosphere operations. It was designed to strafe targets and take out enemy air units, however it fell out of favour due to numerous shortcomings and can frequently be found as part of military surplus.\n\nIt was not intended to land planetside as it doesn’t even have landing gear, but some enterprising individuals have decided to do just that. The mounted charge cannon works perfectly well against armored targets and the interior has been retrofitted to accommodate raid parties and supplies. The extra weight all but guarantees that the ship will be non-recoverable and create massive chaos when it flops onto the surface. | E26: 건틀렛 전투함은 모선에서 발진하여 대기권 저층에서의 작전을 수행하도록 설계되었습니다. 지상에 화력을 지원하거나 공중전에 쓰이도록 만들어졌지만, 각종 결함으로 인해 군의 관심을 잃게 되어 민간에 헐값으로 불하되는 신세가 되었습니다.\n\n우주에 가까운 높은 고도에서 활용할 목적이었기 때문에 지상 착륙을 위한 기어조차 달리지 않았지만, 몇몇 '진취적인' 사람들에겐 그러지 않을 이유가 되지 못했습니다. 어쨌든 장착된 차지 캐논은 중장갑에 아주 탁월했기 때문에, 습격조와 보급품을 실을 수 있도록 내부를 개조했습니다. 이렇게 늘어난 무게는 상승력을 떨어뜨려 추락하는 것 말고는 할 수 없게 되었으며, 지면에 충돌하며 엄청난 혼돈을 일으킬 것을 확실하게 보장해 줍니다. | G26: {=_xlfn.lambda(_xlpm.x,IFERROR(_xlpm.x,""))(VLOOKUP(A26,Merge!$A$122:$B$797,2,FALSE()))} -> #VALUE!
A27: ThingDef+VFEP_WarcasketFoundry.label | B27: ThingDef | C27: VFEP_WarcasketFoundry.label | D27: warcasket foundry | E27: 워캐스킷 주조대 | G27: {=_xlfn.lambda(_xlpm.x,IFERROR(_xlpm.x,""))(VLOOKUP(A27,Merge!$A$122:$B$797,2,FALSE()))} -> #VALUE!
... A34: ThingDef+VFEP_Turret_Cannon.description | B34: ThingDef | C34: VFEP_Turret_Cannon.description | D34: A portable medieval cannon mounted on a 180 degree swivel that launches roughly-rounded balls of steel at a considerable range. The accuracy is rather lacking, but it is a vast improvement compared to catapults while also having a considerably faster fire rate. | E34: 강철로 만든 쇠구슬을 먼 거리로 날려 보내는 중세식 대포입니다. 포가는 180° 회전이 가능하며, 바퀴가 달려있어 위치를 옮길 수 있습니다. 정확도는 상대적으로 떨어지지만, 투석기 같은 것과 비교하면 장족의 발전이라 할 수 있는 데다 발사 속도도 상당히 빠릅니다. | G34: {=_xlfn.lambda(_xlpm.x,IFERROR(_xlpm.x,""))(VLOOKUP(A34,Merge!$A$122:$B$797,2,FALSE()))} -> #VALUE!
A35: ThingDef+VFEP_Turret_Cannon.comps.1.fuelLabel | B35: ThingDef | C35: VFEP_Turret_Cannon.comps.1.fuelLabel | D35: Cannonball | G35: {=_xlfn.lambda(_xlpm.x,IFERROR(_xlpm.x,""))(VLOOKUP(A35,Merge!$A$122:$B$797,2,FALSE()))} -> #VALUE!
A36: ThingDef+VFEP_Turret_Cannon.comps.1.fuelGizmoLabel | B36: ThingDef | C36: VFEP_Turret_Cannon.comps.1.fuelGizmoLabel | D36: Cannonball | G36: {=_xlfn.lambda(_xlpm.x,IFERROR(_xlpm.x,""))(VLOOKUP(A36,Merge!$A$122:$B$797,2,FALSE()))} -> #VALUE!
A37: ThingDef+VFEP_Turret_Cannon.comps.1.outOfFuelMessage | B37: ThingDef | C37: VFEP_Turret_Cannon.comps.1.outOfFuelMessage | D37: Cannot shoot: Needs a cannonball | G37: {=_xlfn.lambda(_xlpm.x,IFERROR(_xlpm.x,""))(VLOOKUP(A37,Merge!$A$122:$B$797,2,FALSE()))} -> #VALUE!
A38: ThingDef+VFEP_Turret_Cannon.comps.3.fuelLabel | B38: ThingDef | C38: VFEP_Turret_Cannon.comps.3.fuelLabel | D38: Cannonball | E38: 남은 포탄 | G38: {=_xlfn.lambda(_xlpm.x,IFERROR(_xlpm.x,""))(VLOOKUP(A38,Merge!$A$122:$B$797,2,FALSE()))} -> #VALUE!
A39: ThingDef+VFEP_Turret_Cannon.comps.3.fuelGizmoLabel | B39: ThingDef | C39: VFEP_Turret_Cannon.comps.3.fuelGizmoLabel | D39: Cannonball | E39: 남은 포탄 | G39: {=_xlfn.lambda(_xlpm.x,IFERROR(_xlpm.x,""))(VLOOKUP(A39,Merge!$A$122:$B$797,2,FALSE()))} -> #VALUE!
A40: ThingDef+VFEP_Turret_Cannon.comps.3.outOfFuelMessage | B40: ThingDef | C40: VFEP_Turret_Cannon.comps.3.outOfFuelMessage | D40: Cannot shoot: Needs a cannonball | E40: 재장전 필요 | G40: {=_xlfn.lambda(_xlpm.x,IFERROR(_xlpm.x,""))(VLOOKUP(A40,Merge!$A$122:$B$797,2,FALSE()))} -> #VALUE!
A41: ThingDef+VFEP_Artillery_Cannon.label | B41: ThingDef | C41: VFEP_Artillery_Cannon.label | D41: cannon | E41: 대포 | G41: {=_xlfn.lambda(_xlpm.x,IFERROR(_xlpm.x,""))(VLOOKUP(A41,Merge!$A$122:$B$797,2,FALSE()))} -> #VALUE!
A42: ThingDef+VFEP_Artillery_Cannon.description | B42: ThingDef | C42: VFEP_Artillery_Cannon.description | D42: A manned gun that launches all kinds of shells. A variation of the mortar with all the benefits and drawbacks, however it has a 90 degree cone of direct-fire in exchange for having an effective firing rate that is twice as fast. | E42: 강철로 만든 쇠구슬을 먼 거리로 날려 보내는 중세식 대포입니다. 정확도는 상대적으로 떨어지지만, 투석기 같은 것과 비교하면 장족의 발전이라 할 수 있는 데다 발사 속도도 상당히 빠릅니다. | G42: {=_xlfn.lambda(_xlpm.x,IFERROR(_xlpm.x,""))(VLOOKUP(A42,Merge!$A$122:$B$797,2,FALSE()))} -> #VALUE!
A43: ThingDef+VFEP_Bullet_Cannonball.label | B43: ThingDef | C43: VFEP_Bullet_Cannonball.label | D43: cannonball | E43: 포탄 | G43: {=_xlfn.lambda(_xlpm.x,IFERROR(_xlpm.x,""))(VLOOKUP(A43,Merge!$A$122:$B$797,2,FALSE()))} -> #VALUE!
A44: ThingDef+VFEP_ShipChunkDebris.label | B44: ThingDef | C44: VFEP_ShipChunkDebris.label | D44: ship chunk debris | E44: 함선 잔해 | G44: {=_xlfn.lambda(_xlpm.x,IFERROR(_xlpm.x,""))(VLOOKUP(A44,Merge!$A$122:$B$797,2,FALSE()))} -> #VALUE!
A45: ThingDef+VFEP_ShipChunkDebris.description | B45: ThingDef | C45: VFEP_ShipChunkDebris.description | D45: A chunk of a combat-grade spacecraft. It seems to have been torn off either by uncontrolled re-entry forces or some kind of weapon. It is densely packed with double-layer armor plating and control systems, which can be acquired by deconstructing it. | E45: 전투함의 잔해입니다. 대기권에 진입하면서 찢겨나왔거나, 어떠한 무기에 맞은 것으로 보입니다. 해체하면 이중 장갑판과 제어 시스템에서 약간의 강철과 부품을 얻을 수 있습니다. | G45: {=_xlfn.lambda(_xlpm.x,IFERROR(_xlpm.x,""))(VLOOKUP(A45,Merge!$A$122:$B$797,2,FALSE()))} -> #VALUE!
A46: ThingDef+VFEP_ShipChunkBattery.label | B46: ThingDef | C46: VFEP_ShipChunkBattery.label | D46: ship chunk battery | E46: 함선 잔해 (축전지) | G46: {=_xlfn.lambda(_xlpm.x,IFERROR(_xlpm.x,""))(VLOOKUP(A46,Merge!$A$122:$B$797,2,FALSE()))} -> #VALUE!
...

Sheet Merge
A1: AbilityDef | B1: =_xlfn.CONCAT($A1,REPLACE(B2,1,1,"+")) -> AbilityDef+odyDef+odyPartDef+ultureDef+amageDef+esignatorDropdownGroupDef+actionDef+ediffDef+istoryEventDef+nteractionDef+ssueDef+obDef+emeDef+VCF.ModDef+awnKindDef+awnsArrivalModeDef+receptDef+aidStrategyDef+ecipeDef+esearchProjectDef+esearchTabDef+itualBehaviorDef+itualOutcomeEffectDef+ulePackDef+cenarioDef+cenPartDef+tatDef+torytellerDef+hingDef+houghtDef+oolCapacityDef+raitDef+FECore.Abilities.AbilityDef+FECore.ExpandableProjectileDef+FECore.Misc.HireableFactionDef+FEPirates.CurseDef+FEPirates.WarcasketDef+orkGiverDef+orldObjectDef+eyed+ | C1: =_xlfn.CONCAT($A1,REPLACE(C2,1,1,"+")) -> AbilityDef+VFEP_FiringFrenzy.description | D1: =_xlfn.CONCAT($A1,REPLACE(D2,1,1,"+")) -> AbilityDef+VFEP_FiringFrenzy.label
B2: =_xlfn.CONCAT($A2,REPLACE(B3,1,1,"+")) -> +odyDef+odyPartDef+ultureDef+amageDef+esignatorDropdownGroupDef+actionDef+ediffDef+istoryEventDef+nteractionDef+ssueDef+obDef+emeDef+VCF.ModDef+awnKindDef+awnsArrivalModeDef+receptDef+aidStrategyDef+ecipeDef+esearchProjectDef+esearchTabDef+itualBehaviorDef+itualOutcomeEffectDef+ulePackDef+cenarioDef+cenPartDef+tatDef+torytellerDef+hingDef+houghtDef+oolCapacityDef+raitDef+FECore.Abilities.AbilityDef+FECore.ExpandableProjectileDef+FECore.Misc.HireableFactionDef+FEPirates.CurseDef+FEPirates.WarcasketDef+orkGiverDef+orldObjectDef+eyed+ | C2: /VFEP_FiringFrenzy.description | D2: /VFEP_FiringFrenzy.label
B3: =_xlfn.CONCAT($A3,REPLACE(B4,1,1,"+")) -> +odyDef+odyPartDef+ultureDef+amageDef+esignatorDropdownGroupDef+actionDef+ediffDef+istoryEventDef+nteractionDef+ssueDef+obDef+emeDef+VCF.ModDef+awnKindDef+awnsArrivalModeDef+receptDef+aidStrategyDef+ecipeDef+esearchProjectDef+esearchTabDef+itualBehaviorDef+itualOutcomeEffectDef+ulePackDef+cenarioDef+cenPartDef+tatDef+torytellerDef+hingDef+houghtDef+oolCapacityDef+raitDef+FECore.Abilities.AbilityDef+FECore.ExpandableProjectileDef+FECore.Misc.HireableFactionDef+FEPirates.CurseDef+FEPirates.WarcasketDef+orkGiverDef+orldObjectDef+eyed+ | C3: 근처에 있는 모든 사람들에게 연사력을 높이고 더 많은 고통을 견딜 수 있도록 영감을 줍니다. 이 효과는 24시간 동안 캐스킷사용자에 부착된 상태로 유지됩니다. | D3: 사격 열광자
A4: BodyDef | B4: =_xlfn.CONCAT($A4,REPLACE(B5,1,1,"+")) -> BodyDef+odyPartDef+ultureDef+amageDef+esignatorDropdownGroupDef+actionDef+ediffDef+istoryEventDef+nteractionDef+ssueDef+obDef+emeDef+VCF.ModDef+awnKindDef+awnsArrivalModeDef+receptDef+aidStrategyDef+ecipeDef+esearchProjectDef+esearchTabDef+itualBehaviorDef+itualOutcomeEffectDef+ulePackDef+cenarioDef+cenPartDef+tatDef+torytellerDef+hingDef+houghtDef+oolCapacityDef+raitDef+FECore.Abilities.AbilityDef+FECore.ExpandableProjectileDef+FECore.Misc.HireableFactionDef+FEPirates.CurseDef+FEPirates.WarcasketDef+orkGiverDef+orldObjectDef+eyed+ | C4: =_xlfn.CONCAT($A4,REPLACE(C5,1,1,"+")) -> BodyDef+VFEP_Spidermine.corePart.parts.0.parts.0.parts.1.customLabel | D4: =_xlfn.CONCAT($A4,REPLACE(D5,1,1,"+")) -> BodyDef+VFEP_Spidermine.corePart.parts.0.parts.0.parts.2.customLabel | E4: =_xlfn.CONCAT($A4,REPLACE(E5,1,1,"+")) -> BodyDef+VFEP_Spidermine.corePart.parts.0.parts.0.parts.3.customLabel | F4: =_xlfn.CONCAT($A4,REPLACE(F5,1,1,"+")) -> BodyDef+VFEP_Spidermine.corePart.parts.0.parts.0.parts.4.customLabel | G4: =_xlfn.CONCAT($A4,REPLACE(G5,1,1,"+")) -> BodyDef+VFEP_Spidermine.corePart.parts.1.customLabel | H4: =_xlfn.CONCAT($A4,REPLACE(H5,1,1,"+")) -> BodyDef+VFEP_Spidermine.corePart.parts.2.customLabel | I4: =_xlfn.CONCAT($A4,REPLACE(I5,1,1,"+")) -> BodyDef+VFEP_Spidermine.label | ... P4: =_xlfn.CONCAT($A4,REPLACE(P5,1,1,"+")) -> BodyDef+VFEP_Wardrone.label
B5: =_xlfn.CONCAT($A5,REPLACE(B6,1,1,"+")) -> +odyPartDef+ultureDef+amageDef+esignatorDropdownGroupDef+actionDef+ediffDef+istoryEventDef+nteractionDef+ssueDef+obDef+emeDef+VCF.ModDef+awnKindDef+awnsArrivalModeDef+receptDef+aidStrategyDef+ecipeDef+esearchProjectDef+esearchTabDef+itualBehaviorDef+itualOutcomeEffectDef+ulePackDef+cenarioDef+cenPartDef+tatDef+torytellerDef+hingDef+houghtDef+oolCapacityDef+raitDef+FECore.Abilities.AbilityDef+FECore.ExpandableProjectileDef+FECore.Misc.HireableFactionDef+FEPirates.CurseDef+FEPirates.WarcasketDef+orkGiverDef+orldObjectDef+eyed+ | C5: /VFEP_Spidermine.corePart.parts.0.parts.0.parts.1.customLabel | D5: /VFEP_Spidermine.corePart.parts.0.parts.0.parts.2.customLabel | E5: /VFEP_Spidermine.corePart.parts.0.parts.0.parts.3.customLabel | F5: /VFEP_Spidermine.corePart.parts.0.parts.0.parts.4.customLabel | G5: /VFEP_Spidermine.corePart.parts.1.customLabel | H5: /VFEP_Spidermine.corePart.parts.2.customLabel | I5: /VFEP_Spidermine.label | J5: /VFEP_Wardrone.corePart.parts.0.parts.0.parts.1.customLabel | K5: /VFEP_Wardrone.corePart.parts.0.parts.0.parts.2.customLabel | L5: /VFEP_Wardrone.corePart.parts.0.parts.0.parts.3.customLabel | M5: /VFEP_Wardrone.corePart.parts.0.parts.0.parts.4.customLabel | N5: /VFEP_Wardrone.corePart.parts.1.customLabel | O5: /VFEP_Wardrone.corePart.parts.2.customLabel | P5: /VFEP_Wardrone.label
B6: =_xlfn.CONCAT($A6,REPLACE(B7,1,1,"+")) -> +odyPartDef+ultureDef+amageDef+esignatorDropdownGroupDef+actionDef+ediffDef+istoryEventDef+nteractionDef+ssueDef+obDef+emeDef+VCF.ModDef+awnKindDef+awnsArrivalModeDef+receptDef+aidStrategyDef+ecipeDef+esearchProjectDef+esearchTabDef+itualBehaviorDef+itualOutcomeEffectDef+ulePackDef+cenarioDef+cenPartDef+tatDef+torytellerDef+hingDef+houghtDef+oolCapacityDef+raitDef+FECore.Abilities.AbilityDef+FECore.ExpandableProjectileDef+FECore.Misc.HireableFactionDef+FEPirates.CurseDef+FEPirates.WarcasketDef+orkGiverDef+orldObjectDef+eyed+ | C6: 왼쪽 시각 센서 | D6: 오른쪽 시각 센서 | E6: 왼쪽 청각 센서 | F6: 오른쪽 청각 센서 | G6: 왼쪽 프로펠러 | H6: 오른쪽 프로펠러 | I6: 거미지뢰 | J6: 왼쪽 시각 센서 | K6: 오른쪽 시각 센서 | L6: 왼쪽 청각 센서 | M6: 오른쪽 청각 센서 | N6: 왼쪽 프로펠러 | O6: 오른쪽 프로펠러 | P6: 전쟁드론
A7: BodyPartDef | B7: =_xlfn.CONCAT($A7,REPLACE(B8,1,1,"+")) -> BodyPartDef+ultureDef+amageDef+esignatorDropdownGroupDef+actionDef+ediffDef+istoryEventDef+nteractionDef+ssueDef+obDef+emeDef+VCF.ModDef+awnKindDef+awnsArrivalModeDef+receptDef+aidStrategyDef+ecipeDef+esearchProjectDef+esearchTabDef+itualBehaviorDef+itualOutcomeEffectDef+ulePackDef+cenarioDef+cenPartDef+tatDef+torytellerDef+hingDef+houghtDef+oolCapacityDef+raitDef+FECore.Abilities.AbilityDef+FECore.ExpandableProjectileDef+FECore.Misc.HireableFactionDef+FEPirates.CurseDef+FEPirates.WarcasketDef+orkGiverDef+orldObjectDef+eyed+ | C7: =_xlfn.CONCAT($A7,REPLACE(C8,1,1,"+")) -> BodyPartDef+VFEP_Base.label | D7: =_xlfn.CONCAT($A7,REPLACE(D8,1,1,"+")) -> BodyPartDef+VFEP_Frame.label | E7: =_xlfn.CONCAT($A7,REPLACE(E8,1,1,"+")) -> BodyPartDef+VFEP_MechanicalJoint.label | F7: =_xlfn.CONCAT($A7,REPLACE(F8,1,1,"+")) -> BodyPartDef+VFEP_MechanicalLeg.label | G7: =_xlfn.CONCAT($A7,REPLACE(G8,1,1,"+")) -> BodyPartDef+VFEP_Propeller.label | H7: =_xlfn.CONCAT($A7,REPLACE(H8,1,1,"+")) -> BodyPartDef+VFEP_Turret.label | I7: =_xlfn.CONCAT($A7,REPLACE(I8,1,1,"+")) -> BodyPartDef+VFEP_TurretBase.label
B8: =_xlfn.CONCAT($A8,REPLACE(B9,1,1,"+")) -> +ultureDef+amageDef+esignatorDropdownGroupDef+actionDef+ediffDef+istoryEventDef+nteractionDef+ssueDef+obDef+emeDef+VCF.ModDef+awnKindDef+awnsArrivalModeDef+receptDef+aidStrategyDef+ecipeDef+esearchProjectDef+esearchTabDef+itualBehaviorDef+itualOutcomeEffectDef+ulePackDef+cenarioDef+cenPartDef+tatDef+torytellerDef+hingDef+houghtDef+oolCapacityDef+raitDef+FECore.Abilities.AbilityDef+FECore.ExpandableProjectileDef+FECore.Misc.HireableFactionDef+FEPirates.CurseDef+FEPirates.WarcasketDef+orkGiverDef+orldObjectDef+eyed+ | C8: /VFEP_Base.label | D8: /VFEP_Frame.label | E8: /VFEP_MechanicalJoint.label | F8: /VFEP_MechanicalLeg.label | G8: /VFEP_Propeller.label | H8: /VFEP_Turret.label | I8: /VFEP_TurretBase.label
B9: =_xlfn.CONCAT($A9,REPLACE(B10,1,1,"+")) -> +ultureDef+amageDef+esignatorDropdownGroupDef+actionDef+ediffDef+istoryEventDef+nteractionDef+ssueDef+obDef+emeDef+VCF.ModDef+awnKindDef+awnsArrivalModeDef+receptDef+aidStrategyDef+ecipeDef+esearchProjectDef+esearchTabDef+itualBehaviorDef+itualOutcomeEffectDef+ulePackDef+cenarioDef+cenPartDef+tatDef+torytellerDef+hingDef+houghtDef+oolCapacityDef+raitDef+FECore.Abilities.AbilityDef+FECore.ExpandableProjectileDef+FECore.Misc.HireableFactionDef+FEPirates.CurseDef+FEPirates.WarcasketDef+orkGiverDef+orldObjectDef+eyed+ | C9: 토대 기반 | D9: 틀 | E9: 이음매 | F9: 기계 다리 | G9: 프로펠러 | H9: 포탑 | I9: 포탑 기반
A10: CultureDef | B10: =_xlfn.CONCAT($A10,REPLACE(B11,1,1,"+")) -> CultureDef+amageDef+esignatorDropdownGroupDef+actionDef+ediffDef+istoryEventDef+nteractionDef+ssueDef+obDef+emeDef+VCF.ModDef+awnKindDef+awnsArrivalModeDef+receptDef+aidStrategyDef+ecipeDef+esearchProjectDef+esearchTabDef+itualBehaviorDef+itualOutcomeEffectDef+ulePackDef+cenarioDef+cenPartDef+tatDef+torytellerDef+hingDef+houghtDef+oolCapacityDef+raitDef+FECore.Abilities.AbilityDef+FECore.ExpandableProjectileDef+FECore.Misc.HireableFactionDef+FEPirates.CurseDef+FEPirates.WarcasketDef+orkGiverDef+orldObjectDef+eyed+ | C10: =_xlfn.CONCAT($A10,REPLACE(C11,1,1,"+")) -> CultureDef+VFEP_Khanate.description | D10: =_xlfn.CONCAT($A10,REPLACE(D11,1,1,"+")) -> CultureDef+VFEP_Khanate.label
B11: =_xlfn.CONCAT($A11,REPLACE(B12,1,1,"+")) -> +amageDef+esignatorDropdownGroupDef+actionDef+ediffDef+istoryEventDef+nteractionDef+ssueDef+obDef+emeDef+VCF.ModDef+awnKindDef+awnsArrivalModeDef+receptDef+aidStrategyDef+ecipeDef+esearchProjectDef+esearchTabDef+itualBehaviorDef+itualOutcomeEffectDef+ulePackDef+cenarioDef+cenPartDef+tatDef+torytellerDef+hingDef+houghtDef+oolCapacityDef+raitDef+FECore.Abilities.AbilityDef+FECore.ExpandableProjectileDef+FECore.Misc.HireableFactionDef+FEPirates.CurseDef+FEPirates.WarcasketDef+orkGiverDef+orldObjectDef+eyed+ | C11: /VFEP_Khanate.description | D11: /VFEP_Khanate.label
B12: =_xlfn.CONCAT($A12,REPLACE(B13,1,1,"+")) -> +amageDef+esignatorDropdownGroupDef+actionDef+ediffDef+istoryEventDef+nteractionDef+ssueDef+obDef+emeDef+VCF.ModDef+awnKindDef+awnsArrivalModeDef+receptDef+aidStrategyDef+ecipeDef+esearchProjectDef+esearchTabDef+itualBehaviorDef+itualOutcomeEffectDef+ulePackDef+cenarioDef+cenPartDef+tatDef+torytellerDef+hingDef+houghtDef+oolCapacityDef+raitDef+FECore.Abilities.AbilityDef+FECore.ExpandableProjectileDef+FECore.Misc.HireableFactionDef+FEPirates.CurseDef+FEPirates.WarcasketDef+orkGiverDef+orldObjectDef+eyed+ | C12: 많은 해적 그룹의 스타일과 관행을 설명하는 광범위한 범주입니다. | D12: 칸의 영토
A13: DamageDef | B13: =_xlfn.CONCAT($A13,REPLACE(B14,1,1,"+")) -> DamageDef+esignatorDropdownGroupDef+actionDef+ediffDef+istoryEventDef+nteractionDef+ssueDef+obDef+emeDef+VCF.ModDef+awnKindDef+awnsArrivalModeDef+receptDef+aidStrategyDef+ecipeDef+esearchProjectDef+esearchTabDef+itualBehaviorDef+itualOutcomeEffectDef+ulePackDef+cenarioDef+cenPartDef+tatDef+torytellerDef+hingDef+houghtDef+oolCapacityDef+raitDef+FECore.Abilities.AbilityDef+FECore.ExpandableProjectileDef+FECore.Misc.HireableFactionDef+FEPirates.CurseDef+FEPirates.WarcasketDef+orkGiverDef+orldObjectDef+eyed+ | C13: =_xlfn.CONCAT($A13,REPLACE(C14,1,1,"+")) -> DamageDef+VFEP_GravityHammerAttack.deathMessage | D13: =_xlfn.CONCAT($A13,REPLACE(D14,1,1,"+")) -> DamageDef+VFEP_GravityHammerAttack.label
B14: =_xlfn.CONCAT($A14,REPLACE(B15,1,1,"+")) -> +esignatorDropdownGroupDef+actionDef+ediffDef+istoryEventDef+nteractionDef+ssueDef+obDef+emeDef+VCF.ModDef+awnKindDef+awnsArrivalModeDef+receptDef+aidStrategyDef+ecipeDef+esearchProjectDef+esearchTabDef+itualBehaviorDef+itualOutcomeEffectDef+ulePackDef+cenarioDef+cenPartDef+tatDef+torytellerDef+hingDef+houghtDef+oolCapacityDef+raitDef+FECore.Abilities.AbilityDef+FECore.ExpandableProjectileDef+FECore.Misc.HireableFactionDef+FEPirates.CurseDef+FEPirates.WarcasketDef+orkGiverDef+orldObjectDef+eyed+ | C14: /VFEP_GravityHammerAttack.deathMessage | D14: /VFEP_GravityHammerAttack.label
B15: =_xlfn.CONCAT($A15,REPLACE(B16,1,1,"+")) -> +esignatorDropdownGroupDef+actionDef+ediffDef+istoryEventDef+nteractionDef+ssueDef+obDef+emeDef+VCF.ModDef+awnKindDef+awnsArrivalModeDef+receptDef+aidStrategyDef+ecipeDef+esearchProjectDef+esearchTabDef+itualBehaviorDef+itualOutcomeEffectDef+ulePackDef+cenarioDef+cenPartDef+tatDef+torytellerDef+hingDef+houghtDef+oolCapacityDef+raitDef+FECore.Abilities.AbilityDef+FECore.ExpandableProjectileDef+FECore.Misc.HireableFactionDef+FEPirates.CurseDef+FEPirates.WarcasketDef+orkGiverDef+orldObjectDef+eyed+ | C15: {0} 명이 박살나 죽었습니다. | D15: 중력 망치 공격
A16: DesignatorDropdownGroupDef | B16: =_xlfn.CONCAT($A16,REPLACE(B17,1,1,"+")) -> DesignatorDropdownGroupDef+actionDef+ediffDef+istoryEventDef+nteractionDef+ssueDef+obDef+emeDef+VCF.ModDef+awnKindDef+awnsArrivalModeDef+receptDef+aidStrategyDef+ecipeDef+esearchProjectDef+esearchTabDef+itualBehaviorDef+itualOutcomeEffectDef+ulePackDef+cenarioDef+cenPartDef+tatDef+torytellerDef+hingDef+houghtDef+oolCapacityDef+raitDef+FECore.Abilities.AbilityDef+FECore.ExpandableProjectileDef+FECore.Misc.HireableFactionDef+FEPirates.CurseDef+FEPirates.WarcasketDef+orkGiverDef+orldObjectDef+eyed+ | C16: =_xlfn.CONCAT($A16,REPLACE(C17,1,1,"+")) -> DesignatorDropdownGroupDef+VFEP_WarcasketWeapon.label
B17: =_xlfn.CONCAT($A17,REPLACE(B18,1,1,"+")) -> +actionDef+ediffDef+istoryEventDef+nteractionDef+ssueDef+obDef+emeDef+VCF.ModDef+awnKindDef+awnsArrivalModeDef+receptDef+aidStrategyDef+ecipeDef+esearchProjectDef+esearchTabDef+itualBehaviorDef+itualOutcomeEffectDef+ulePackDef+cenarioDef+cenPartDef+tatDef+torytellerDef+hingDef+houghtDef+oolCapacityDef+raitDef+FECore.Abilities.AbilityDef+FECore.ExpandableProjectileDef+FECore.Misc.HireableFactionDef+FEPirates.CurseDef+FEPirates.WarcasketDef+orkGiverDef+orldObjectDef+eyed+ | C17: /VFEP_WarcasketWeapon.label
B18: =_xlfn.CONCAT($A18,REPLACE(B19,1,1,"+")) -> +actionDef+ediffDef+istoryEventDef+nteractionDef+ssueDef+obDef+emeDef+VCF.ModDef+awnKindDef+awnsArrivalModeDef+receptDef+aidStrategyDef+ecipeDef+esearchProjectDef+esearchTabDef+itualBehaviorDef+itualOutcomeEffectDef+ulePackDef+cenarioDef+cenPartDef+tatDef+torytellerDef+hingDef+houghtDef+oolCapacityDef+raitDef+FECore.Abilities.AbilityDef+FECore.ExpandableProjectileDef+FECore.Misc.HireableFactionDef+FEPirates.CurseDef+FEPirates.WarcasketDef+orkGiverDef+orldObjectDef+eyed+ | C18: 워캐스켓 무기들
A19: FactionDef | B19: =_xlfn.CONCAT($A19,REPLACE(B20,1,1,"+")) -> FactionDef+ediffDef+istoryEventDef+nteractionDef+ssueDef+obDef+emeDef+VCF.ModDef+awnKindDef+awnsArrivalModeDef+receptDef+aidStrategyDef+ecipeDef+esearchProjectDef+esearchTabDef+itualBehaviorDef+itualOutcomeEffectDef+ulePackDef+cenarioDef+cenPartDef+tatDef+torytellerDef+hingDef+houghtDef+oolCapacityDef+raitDef+FECore.Abilities.AbilityDef+FECore.ExpandableProjectileDef+FECore.Misc.HireableFactionDef+FEPirates.CurseDef+FEPirates.WarcasketDef+orkGiverDef+orldObjectDef+eyed+ | C19: =_xlfn.CONCAT($A19,REPLACE(C20,1,1,"+")) -> FactionDef+VFEP_Junkers.description | D19: =_xlfn.CONCAT($A19,REPLACE(D20,1,1,"+")) -> FactionDef+VFEP_Junkers.label | E19: =_xlfn.CONCAT($A19,REPLACE(E20,1,1,"+")) -> FactionDef+VFEP_Junkers.leaderTitle | F19: =_xlfn.CONCAT($A19,REPLACE(F20,1,1,"+")) -> FactionDef+VFEP_Junkers.pawnSingular | G19: =_xlfn.CONCAT($A19,REPLACE(G20,1,1,"+")) -> FactionDef+VFEP_Junkers.pawnsPlural | H19: =_xlfn.CONCAT($A19,REPLACE(H20,1,1,"+")) -> FactionDef+VFEP_Mercenaries.description | I19: =_xlfn.CONCAT($A19,REPLACE(I20,1,1,"+")) -> FactionDef+VFEP_Mercenaries.label | ... P19: =_xlfn.CONCAT($A19,REPLACE(P20,1,1,"+")) -> FactionDef+VFEP_PlayerPirate.pawnsPlural
B20: =_xlfn.CONCAT($A20,REPLACE(B21,1,1,"+")) -> +ediffDef+istoryEventDef+nteractionDef+ssueDef+obDef+emeDef+VCF.ModDef+awnKindDef+awnsArrivalModeDef+receptDef+aidStrategyDef+ecipeDef+esearchProjectDef+esearchTabDef+itualBehaviorDef+itualOutcomeEffectDef+ulePackDef+cenarioDef+cenPartDef+tatDef+torytellerDef+hingDef+houghtDef+oolCapacityDef+raitDef+FECore.Abilities.AbilityDef+FECore.ExpandableProjectileDef+FECore.Misc.HireableFactionDef+FEPirates.CurseDef+FEPirates.WarcasketDef+orkGiverDef+orldObjectDef+eyed+ | C20: /VFEP_Junkers.description | D20: /VFEP_Junkers.label | E20: /VFEP_Junkers.leaderTitle | F20: /VFEP_Junkers.pawnSingular | G20: /VFEP_Junkers.pawnsPlural | H20: /VFEP_Mercenaries.description | I20: /VFEP_Mercenaries.label | J20: /VFEP_Mercenaries.leaderTitle | K20: /VFEP_Mercenaries.pawnSingular | L20: /VFEP_Mercenaries.pawnsPlural | M20: /VFEP_PlayerPirate.description | N20: /VFEP_PlayerPirate.label | O20: /VFEP_PlayerPirate.pawnSingular | P20: /VFEP_PlayerPirate.pawnsPlural
B21: =_xlfn.CONCAT($A21,REPLACE(B22,1,1,"+")) -> +ediffDef+istoryEventDef+nteractionDef+ssueDef+obDef+emeDef+VCF.ModDef+awnKindDef+awnsArrivalModeDef+receptDef+aidStrategyDef+ecipeDef+esearchProjectDef+esearchTabDef+itualBehaviorDef+itualOutcomeEffectDef+ulePackDef+cenarioDef+cenPartDef+tatDef+torytellerDef+hingDef+houghtDef+oolCapacityDef+raitDef+FECore.Abilities.AbilityDef+FECore.ExpandableProjectileDef+FECore.Misc.HireableFactionDef+FEPirates.CurseDef+FEPirates.WarcasketDef+orkGiverDef+orldObjectDef+eyed+ | C21: 서로 싸우는 대신 외부인들과 싸우기로 합의한 느슨한 해적 갱단 연합입니다. 해적들은 씨를 뿌리지도, 짓지도 않고, 거래도 거의 하지 않습니다. 개인의 힘과 무자비함을 중요시하는 피와 명예문화에 의해, 그들은 더 생산적인 이웃을 습격하고 강탈함으로써 그들 자신을 풍요롭게 합니다. 정커들은 워캐스킷 기술을 이용하여 금속 무덤에 스스로를 봉인하고, 그곳에서 그들은 습격하고, 훔치고, 약탈하고, 필연적으로 죽게 됩니다. 그들은 근거리 무기를 거의 사용하지 않으며 강력한 무기를 충분히 사용하기 위해 적과 거리를 두는 것을 선호합니다. | D21: 정커스 | E21: 칸 | F21: 정커 | G21: 정커스 | H21: 정치인들과 거대 기업들에 의해 승인되고 통치되는 준군사 조직입니다. 용병들은 씨를 뿌리지도 않고, 짓지도 않고, 거래도 거의 하지 않습니다. 개인의 힘과 무지비함을 중요시하는 피와 명예 문화에 의해, 그들은 더 생산적인 이웃을 습격하고 강탈함으로써 그들 자신을 풍요롭게 합니다. 용병들은 그들의 기업 지배자들의 목표를 제거하기 위한 무기이자 방패들입니다. 다른 해적 파벌과는 달리 용병들은 의사소통이 가능하고 친구가 될 수 있지만, 그들은 무역과 연구와 관련하여 제공할 것이 거의 없습니다. | I21: 용병들 | J21: 장군 | K21: 용병 | L21: 용병들 | M21: 작은 해적 만입니다.. | N21: 새로운 만 | O21: 해적 | P21: 해적들
A22: HediffDef | B22: =_xlfn.CONCAT($A22,REPLACE(B23,1,1,"+")) -> HediffDef+istoryEventDef+nteractionDef+ssueDef+obDef+emeDef+VCF.ModDef+awnKindDef+awnsArrivalModeDef+receptDef+aidStrategyDef+ecipeDef+esearchProjectDef+esearchTabDef+itualBehaviorDef+itualOutcomeEffectDef+ulePackDef+cenarioDef+cenPartDef+tatDef+torytellerDef+hingDef+houghtDef+oolCapacityDef+raitDef+FECore.Abilities.AbilityDef+FECore.ExpandableProjectileDef+FECore.Misc.HireableFactionDef+FEPirates.CurseDef+FEPirates.WarcasketDef+orkGiverDef+orldObjectDef+eyed+ | C22: =_xlfn.CONCAT($A22,REPLACE(C23,1,1,"+")) -> HediffDef+VFEP_FiringFrenzy.description | D22: =_xlfn.CONCAT($A22,REPLACE(D23,1,1,"+")) -> HediffDef+VFEP_FiringFrenzy.label | E22: =_xlfn.CONCAT($A22,REPLACE(E23,1,1,"+")) -> HediffDef+VFEP_FiringFrenzyBuff.description | F22: =_xlfn.CONCAT($A22,REPLACE(F23,1,1,"+")) -> HediffDef+VFEP_FiringFrenzyBuff.label | G22: =_xlfn.CONCAT($A22,REPLACE(G23,1,1,"+")) -> HediffDef+VFEP_HypothermicSlowdown.description | H22: =_xlfn.CONCAT($A22,REPLACE(H23,1,1,"+")) -> HediffDef+VFEP_HypothermicSlowdown.label | I22: =_xlfn.CONCAT($A22,REPLACE(I23,1,1,"+")) -> HediffDef+VFEP_HypothermicSlowdown.stages.0.label | ... U22: =_xlfn.CONCAT($A22,REPLACE(U23,1,1,"+")) -> HediffDef+VFEP_SiegeMode.labelNoun
B23: =_xlfn.CONCAT($A23,REPLACE(B24,1,1,"+")) -> +istoryEventDef+nteractionDef+ssueDef+obDef+emeDef+VCF.ModDef+awnKindDef+awnsArrivalModeDef+receptDef+aidStrategyDef+ecipeDef+esearchProjectDef+esearchTabDef+itualBehaviorDef+itualOutcomeEffectDef+ulePackDef+cenarioDef+cenPartDef+tatDef+torytellerDef+hingDef+houghtDef+oolCapacityDef+raitDef+FECore.Abilities.AbilityDef+FECore.ExpandableProjectileDef+FECore.Misc.HireableFactionDef+FEPirates.CurseDef+FEPirates.WarcasketDef+orkGiverDef+orldObjectDef+eyed+ | C23: /VFEP_FiringFrenzy.description | D23: /VFEP_FiringFrenzy.label | E23: /VFEP_FiringFrenzyBuff.description | F23: /VFEP_FiringFrenzyBuff.label | G23: /VFEP_HypothermicSlowdown.description | H23: /VFEP_HypothermicSlowdown.label | I23: /VFEP_HypothermicSlowdown.stages.0.label | J23: /VFEP_HypothermicSlowdown.stages.1.label | K23: /VFEP_HypothermicSlowdown.stages.2.label | L23: /VFEP_HypothermicSlowdown.stages.3.label | M23: /VFEP_HypothermicSlowdown.stages.4.label | N23: /VFEP_KillItself.description | O23: /VFEP_KillItself.label | P23: /VFEP_KillItself.stages.0.label | Q23: /VFEP_RumAsIngredient.description | R23: /VFEP_RumAsIngredient.label | S23: /VFEP_SiegeMode.description | T23: /VFEP_SiegeMode.label | U23: /VFEP_SiegeMode.labelNoun
B24: =_xlfn.CONCAT($A24,REPLACE(B25,1,1,"+")) -> +istoryEventDef+nteractionDef+ssueDef+obDef+emeDef+VCF.ModDef+awnKindDef+awnsArrivalModeDef+receptDef+aidStrategyDef+ecipeDef+esearchProjectDef+esearchTabDef+itualBehaviorDef+itualOutcomeEffectDef+ulePackDef+cenarioDef+cenPartDef+tatDef+torytellerDef+hingDef+houghtDef+oolCapacityDef+raitDef+FECore.Abilities.AbilityDef+FECore.ExpandableProjectileDef+FECore.Misc.HireableFactionDef+FEPirates.CurseDef+FEPirates.WarcasketDef+orkGiverDef+orldObjectDef+eyed+ | C24: 이 사람은 주변의 모든 사람들에게 영감을 주기 위해 특별한 능력을 사용하고 있습니다. 효과 반경 내의 모든 사람은 사격 조준 시간을 50% 단축하고 고통 쇼크 임계값을 50% 증가시킵니다. | D24: 사격 열광자 | E24: 누군가가 근처에서 사격 열광자의 능력을 사용하여 이 사람이 더 빨리 사격하고 더 많은 육체적 고통을 견뎌내도록 영감을 주고 있습니다. | F24: 사격 열광자 | G24: 위험할 정도로 낮은 코어 체온. 다시 따뜻하게 하지 않으면, 저체온 속도 저하는 더 심해지고 사망으로 끝납니다. 환자가 다시 따뜻해지면 빠르게 회복됩니다. | H24: 저체온 속도 저하 | I24: 미미한 | J24: 미미한 | K24: 가벼움 | L24: 심각함 | M24: 극심함 | N24: . | O24: 스스로 목숨을 끊다. | P24: 미미한 | Q24: 이 정착민은 럼주를 재료로 한 칵테일을 마셨습니다. 공복률 15% 감소. | R24: 럼주를 베이스로 한 칵테일 | S24: 공성 모드 | T24: 공성 모드 | U24: 공성 모드
A25: HistoryEventDef | B25: =_xlfn.CONCAT($A25,REPLACE(B26,1,1,"+")) -> HistoryEventDef+nteractionDef+ssueDef+obDef+emeDef+VCF.ModDef+awnKindDef+awnsArrivalModeDef+receptDef+aidStrategyDef+ecipeDef+esearchProjectDef+esearchTabDef+itualBehaviorDef+itualOutcomeEffectDef+ulePackDef+cenarioDef+cenPartDef+tatDef+torytellerDef+hingDef+houghtDef+oolCapacityDef+raitDef+FECore.Abilities.AbilityDef+FECore.ExpandableProjectileDef+FECore.Misc.HireableFactionDef+FEPirates.CurseDef+FEPirates.WarcasketDef+orkGiverDef+orldObjectDef+eyed+ | C25: =_xlfn.CONCAT($A25,REPLACE(C26,1,1,"+")) -> HistoryEventDef+VFEP_CrewmanDied.label
B26: =_xlfn.CONCAT($A26,REPLACE(B27,1,1,"+")) -> +nteractionDef+ssueDef+obDef+emeDef+VCF.ModDef+awnKindDef+awnsArrivalModeDef+receptDef+aidStrategyDef+ecipeDef+esearchProjectDef+esearchTabDef+itualBehaviorDef+itualOutcomeEffectDef+ulePackDef+cenarioDef+cenPartDef+tatDef+torytellerDef+hingDef+houghtDef+oolCapacityDef+raitDef+FECore.Abilities.AbilityDef+FECore.ExpandableProjectileDef+FECore.Misc.HireableFactionDef+FEPirates.CurseDef+FEPirates.WarcasketDef+orkGiverDef+orldObjectDef+eyed+ | C26: /VFEP_CrewmanDied.label
B27: =_xlfn.CONCAT($A27,REPLACE(B28,1,1,"+")) -> +nteractionDef+ssueDef+obDef+emeDef+VCF.ModDef+awnKindDef+awnsArrivalModeDef+receptDef+aidStrategyDef+ecipeDef+esearchProjectDef+esearchTabDef+itualBehaviorDef+itualOutcomeEffectDef+ulePackDef+cenarioDef+cenPartDef+tatDef+torytellerDef+hingDef+houghtDef+oolCapacityDef+raitDef+FECore.Abilities.AbilityDef+FECore.ExpandableProjectileDef+FECore.Misc.HireableFactionDef+FEPirates.CurseDef+FEPirates.WarcasketDef+orkGiverDef+orldObjectDef+eyed+ | C27: 승무원 사망
A28: InteractionDef | B28: =_xlfn.CONCAT($A28,REPLACE(B29,1,1,"+")) -> InteractionDef+ssueDef+obDef+emeDef+VCF.ModDef+awnKindDef+awnsArrivalModeDef+receptDef+aidStrategyDef+ecipeDef+esearchProjectDef+esearchTabDef+itualBehaviorDef+itualOutcomeEffectDef+ulePackDef+cenarioDef+cenPartDef+tatDef+torytellerDef+hingDef+houghtDef+oolCapacityDef+raitDef+FECore.Abilities.AbilityDef+FECore.ExpandableProjectileDef+FECore.Misc.HireableFactionDef+FEPirates.CurseDef+FEPirates.WarcasketDef+orkGiverDef+orldObjectDef+eyed+ | C28: =_xlfn.CONCAT($A28,REPLACE(C29,1,1,"+")) -> InteractionDef+VFEP_Speech_Shanties.label | D28: =_xlfn.CONCAT($A28,REPLACE(D29,1,1,"+")) -> InteractionDef+VFEP_Speech_Shanties.logRulesInitiator.rulesStrings.0 | E28: =_xlfn.CONCAT($A28,REPLACE(E29,1,1,"+")) -> InteractionDef+VFEP_Speech_Shanties.logRulesInitiator.rulesStrings.1 | F28: =_xlfn.CONCAT($A28,REPLACE(F29,1,1,"+")) -> InteractionDef+VFEP_Speech_Shanties.logRulesInitiator.rulesStrings.10 | G28: =_xlfn.CONCAT($A28,REPLACE(G29,1,1,"+")) -> InteractionDef+VFEP_Speech_Shanties.logRulesInitiator.rulesStrings.11 | H28: =_xlfn.CONCAT($A28,REPLACE(H29,1,1,"+")) -> InteractionDef+VFEP_Speech_Shanties.logRulesInitiator.rulesStrings.12 | I28: =_xlfn.CONCAT($A28,REPLACE(I29,1,1,"+")) -> InteractionDef+VFEP_Speech_Shanties.logRulesInitiator.rulesStrings.13 | ... AE28: =_xlfn.CONCAT($A28,REPLACE(AE29,1,1,"+")) -> InteractionDef+VFEP_Speech_Shanties.logRulesInitiator.rulesStrings.9
B29: =_xlfn.CONCAT($A29,REPLACE(B30,1,1,"+")) -> +ssueDef+obDef+emeDef+VCF.ModDef+awnKindDef+awnsArrivalModeDef+receptDef+aidStrategyDef+ecipeDef+esearchProjectDef+esearchTabDef+itualBehaviorDef+itualOutcomeEffectDef+ulePackDef+cenarioDef+cenPartDef+tatDef+torytellerDef+hingDef+houghtDef+oolCapacityDef+raitDef+FECore.Abilities.AbilityDef+FECore.ExpandableProjectileDef+FECore.Misc.HireableFactionDef+FEPirates.CurseDef+FEPirates.WarcasketDef+orkGiverDef+orldObjectDef+eyed+ | C29: /VFEP_Speech_Shanties.label | D29: /VFEP_Speech_Shanties.logRulesInitiator.rulesStrings.0 | E29: /VFEP_Speech_Shanties.logRulesInitiator.rulesStrings.1 | F29: /VFEP_Speech_Shanties.logRulesInitiator.rulesStrings.10 | G29: /VFEP_Speech_Shanties.logRulesInitiator.rulesStrings.11 | H29: /VFEP_Speech_Shanties.logRulesInitiator.rulesStrings.12 | I29: /VFEP_Speech_Shanties.logRulesInitiator.rulesStrings.13 | J29: /VFEP_Speech_Shanties.logRulesInitiator.rulesStrings.14 | K29: /VFEP_Speech_Shanties.logRulesInitiator.rulesStrings.15 | L29: /VFEP_Speech_Shanties.logRulesInitiator.rulesStrings.16 | M29: /VFEP_Speech_Shanties.logRulesInitiator.rulesStrings.17 | N29: /VFEP_Speech_Shanties.logRulesInitiator.rulesStrings.18 | O29: /VFEP_Speech_Shanties.logRulesInitiator.rulesStrings.19 | P29: /VFEP_Speech_Shanties.logRulesInitiator.rulesStrings.2 | Q29: /VFEP_Speech_Shanties.logRulesInitiator.rulesStrings.20 | R29: /VFEP_Speech_Shanties.logRulesInitiator.rulesStrings.21 | S29: /VFEP_Speech_Shanties.logRulesInitiator.rulesStrings.22 | T29: /VFEP_Speech_Shanties.logRulesInitiator.rulesStrings.23 | U29: /VFEP_Speech_Shanties.logRulesInitiator.rulesStrings.24 | V29: /VFEP_Speech_Shanties.logRulesInitiator.rulesStrings.25 | W29: /VFEP_Speech_Shanties.logRulesInitiator.rulesStrings.26 | X29: /VFEP_Speech_Shanties.logRulesInitiator.rulesStrings.27 | Y29: /VFEP_Speech_Shanties.logRulesInitiator.rulesStrings.3 | Z29: /VFEP_Speech_Shanties.logRulesInitiator.rulesStrings.4 | AA29: /VFEP_Speech_Shanties.logRulesInitiator.rulesStrings.5 | AB29: /VFEP_Speech_Shanties.logRulesInitiator.rulesStrings.6 | AC29: /VFEP_Speech_Shanties.logRulesInitiator.rulesStrings.7 | AD29: /VFEP_Speech_Shanties.logRulesInitiator.rulesStrings.8 | AE29: /VFEP_Speech_Shanties.logRulesInitiator.rulesStrings.9
B30: =_xlfn.CONCAT($A30,REPLACE(B31,1,1,"+")) -> +ssueDef+obDef+emeDef+VCF.ModDef+awnKindDef+awnsArrivalModeDef+receptDef+aidStrategyDef+ecipeDef+esearchProjectDef+esearchTabDef+itualBehaviorDef+itualOutcomeEffectDef+ulePackDef+cenarioDef+cenPartDef+tatDef+torytellerDef+hingDef+houghtDef+oolCapacityDef+raitDef+FECore.Abilities.AbilityDef+FECore.ExpandableProjectileDef+FECore.Misc.HireableFactionDef+FEPirates.CurseDef+FEPirates.WarcasketDef+orkGiverDef+orldObjectDef+eyed+ | C30: 뱃노래 부르기 | D30: r_logentry->[INITIATOR_nameDef] [spokeof] [speechtopic]. | E30: speechtopic->괴혈병을 피하기 위해 [Vegetable]를 찾는 중 | F30: speechtopic->함께 힘을 합쳐[Enemy]를 물리치기 | G30: speechtopic->전투중 [Gore] 즐기기 | H30: speechtopic->동지애의 의미 | I30: speechtopic->승무원들의 동지애 | J30: speechtopic->[AdjectiveBadass]이 되지 않고 [AdjectiveBadass]이 되는 방법 | K30: speechtopic->승무원이 얼마나 [AdjectiveBadass] 나쁜지 | L30: speechtopic->[AdjectiveNatural] [TerrainFeature] | M30: speechtopic->승무원의 [AdjectiveLarge] 잠재력 | N30: speechtopic->모든 승무원의 [PersonalCharacteristic] | O30: speechtopic->승무원의 적의 끔찍한[PersonalCharacteristic] | P30: speechtopic->적을 약탈하면서 [AdjectiveFriendly]이 되는 방법 | Q30: speechtopic(p=0.25)->그룹으로 함께 뭉치기 | R30: speechtopic(p=0.25)->비극을 헤치고 앞으로 나아가는 길, 승무원으로서 함께 뭉치기 | S30: speechtopic(p=0.25)->승무원과 그 중요성 | T30: speechtopic(p=0.25)->최강자의 생존 | U30: speechtopic(p=0.25)->공동의 고난을 통한 승리 | V30: speechtopic(p=0.25)->적의 죽음을 동기 부여로 삼기 | W30: speechtopic(p=0.25)->강한 손과 마음, 함께 일하는 것 | X30: speechtopic(p=0.25)->약자들을 이기고 생존할 권리 | Y30: speechtopic->[AnimalBadass]을 단백질 공급원으로 사용 | Z30: speechtopic->[Game]이 승무원으로 활동하도록 훈련하는 방법 | AA30: speechtopic->습격에서 [Weapon] 사용 | AB30: speechtopic->[TerrainFeature]과 [TerrainFeature]을 통한 약탈 | AC30: speechtopic->승무원 모두가[PersonFamily]와 [PersonFamily]인 방법 | AD30: speechtopic->승무원에게 [PersonJob]의 필요성 | AE30: speechtopic->[PersonBadass]와의 대결
A31: IssueDef | B31: =_xlfn.CONCAT($A31,REPLACE(B32,1,1,"+")) -> IssueDef+obDef+emeDef+VCF.ModDef+awnKindDef+awnsArrivalModeDef+receptDef+aidStrategyDef+ecipeDef+esearchProjectDef+esearchTabDef+itualBehaviorDef+itualOutcomeEffectDef+ulePackDef+cenarioDef+cenPartDef+tatDef+torytellerDef+hingDef+houghtDef+oolCapacityDef+raitDef+FECore.Abilities.AbilityDef+FECore.ExpandableProjectileDef+FECore.Misc.HireableFactionDef+FEPirates.CurseDef+FEPirates.WarcasketDef+orkGiverDef+orldObjectDef+eyed+ | C31: =_xlfn.CONCAT($A31,REPLACE(C32,1,1,"+")) -> IssueDef+VFEP_Camaraderie.label
B32: =_xlfn.CONCAT($A32,REPLACE(B33,1,1,"+")) -> +obDef+emeDef+VCF.ModDef+awnKindDef+awnsArrivalModeDef+receptDef+aidStrategyDef+ecipeDef+esearchProjectDef+esearchTabDef+itualBehaviorDef+itualOutcomeEffectDef+ulePackDef+cenarioDef+cenPartDef+tatDef+torytellerDef+hingDef+houghtDef+oolCapacityDef+raitDef+FECore.Abilities.AbilityDef+FECore.ExpandableProjectileDef+FECore.Misc.HireableFactionDef+FEPirates.CurseDef+FEPirates.WarcasketDef+orkGiverDef+orldObjectDef+eyed+ | C32: /VFEP_Camaraderie.label
B33: =_xlfn.CONCAT($A33,REPLACE(B34,1,1,"+")) -> +obDef+emeDef+VCF.ModDef+awnKindDef+awnsArrivalModeDef+receptDef+aidStrategyDef+ecipeDef+esearchProjectDef+esearchTabDef+itualBehaviorDef+itualOutcomeEffectDef+ulePackDef+cenarioDef+cenPartDef+tatDef+torytellerDef+hingDef+houghtDef+oolCapacityDef+raitDef+FECore.Abilities.AbilityDef+FECore.ExpandableProjectileDef+FECore.Misc.HireableFactionDef+FEPirates.CurseDef+FEPirates.WarcasketDef+orkGiverDef+orldObjectDef+eyed+ | C33: 동지애
A34: JobDef | B34: =_xlfn.CONCAT($A34,REPLACE(B35,1,1,"+")) -> JobDef+emeDef+VCF.ModDef+awnKindDef+awnsArrivalModeDef+receptDef+aidStrategyDef+ecipeDef+esearchProjectDef+esearchTabDef+itualBehaviorDef+itualOutcomeEffectDef+ulePackDef+cenarioDef+cenPartDef+tatDef+torytellerDef+hingDef+houghtDef+oolCapacityDef+raitDef+FECore.Abilities.AbilityDef+FECore.ExpandableProjectileDef+FECore.Misc.HireableFactionDef+FEPirates.CurseDef+FEPirates.WarcasketDef+orkGiverDef+orldObjectDef+eyed+ | C34: =_xlfn.CONCAT($A34,REPLACE(C35,1,1,"+")) -> JobDef+VFEP_DoWelding.reportString | D34: =_xlfn.CONCAT($A34,REPLACE(D35,1,1,"+")) -> JobDef+VFEP_EntombIn.reportString | E34: =_xlfn.CONCAT($A34,REPLACE(E35,1,1,"+")) -> JobDef+VFEP_EquipFromWeaponBox.reportString | F34: =_xlfn.CONCAT($A34,REPLACE(F35,1,1,"+")) -> JobDef+VFEP_GotoAndExplode.reportString
B35: =_xlfn.CONCAT($A35,REPLACE(B36,1,1,"+")) -> +emeDef+VCF.ModDef+awnKindDef+awnsArrivalModeDef+receptDef+aidStrategyDef+ecipeDef+esearchProjectDef+esearchTabDef+itualBehaviorDef+itualOutcomeEffectDef+ulePackDef+cenarioDef+cenPartDef+tatDef+torytellerDef+hingDef+houghtDef+oolCapacityDef+raitDef+FECore.Abilities.AbilityDef+FECore.ExpandableProjectileDef+FECore.Misc.HireableFactionDef+FEPirates.CurseDef+FEPirates.WarcasketDef+orkGiverDef+orldObjectDef+eyed+ | C35: /VFEP_DoWelding.reportString | D35: /VFEP_EntombIn.reportString | E35: /VFEP_EquipFromWeaponBox.reportString | F35: /VFEP_GotoAndExplode.reportString
B36: =_xlfn.CONCAT($A36,REPLACE(B37,1,1,"+")) -> +emeDef+VCF.ModDef+awnKindDef+awnsArrivalModeDef+receptDef+aidStrategyDef+ecipeDef+esearchProjectDef+esearchTabDef+itualBehaviorDef+itualOutcomeEffectDef+ulePackDef+cenarioDef+cenPartDef+tatDef+torytellerDef+hingDef+houghtDef+oolCapacityDef+raitDef+FECore.Abilities.AbilityDef+FECore.ExpandableProjectileDef+FECore.Misc.HireableFactionDef+FEPirates.CurseDef+FEPirates.WarcasketDef+orkGiverDef+orldObjectDef+eyed+ | C36: TargetA에서 TargetB 용접하기. | D36: TargetA에 매장하기. | E36: TargetA 장착하기. | F36: 이동중.
A37: MemeDef | B37: =_xlfn.CONCAT($A37,REPLACE(B38,1,1,"+")) -> MemeDef+VCF.ModDef+awnKindDef+awnsArrivalModeDef+receptDef+aidStrategyDef+ecipeDef+esearchProjectDef+esearchTabDef+itualBehaviorDef+itualOutcomeEffectDef+ulePackDef+cenarioDef+cenPartDef+tatDef+torytellerDef+hingDef+houghtDef+oolCapacityDef+raitDef+FECore.Abilities.AbilityDef+FECore.ExpandableProjectileDef+FECore.Misc.HireableFactionDef+FEPirates.CurseDef+FEPirates.WarcasketDef+orkGiverDef+orldObjectDef+eyed+ | C37: =_xlfn.CONCAT($A37,REPLACE(C38,1,1,"+")) -> MemeDef+VFEP_PirateMeme.description | D37: =_xlfn.CONCAT($A37,REPLACE(D38,1,1,"+")) -> MemeDef+VFEP_PirateMeme.descriptionMaker.rules.rulesStrings.0 | E37: =_xlfn.CONCAT($A37,REPLACE(E38,1,1,"+")) -> MemeDef+VFEP_PirateMeme.descriptionMaker.rules.rulesStrings.1 | F37: =_xlfn.CONCAT($A37,REPLACE(F38,1,1,"+")) -> MemeDef+VFEP_PirateMeme.descriptionMaker.rules.rulesStrings.10 | G37: =_xlfn.CONCAT($A37,REPLACE(G38,1,1,"+")) -> MemeDef+VFEP_PirateMeme.descriptionMaker.rules.rulesStrings.11 | H37: =_xlfn.CONCAT($A37,REPLACE(H38,1,1,"+")) -> MemeDef+VFEP_PirateMeme.descriptionMaker.rules.rulesStrings.12 | I37: =_xlfn.CONCAT($A37,REPLACE(I38,1,1,"+")) -> MemeDef+VFEP_PirateMeme.descriptionMaker.rules.rulesStrings.13 | ... AT37: =_xlfn.CONCAT($A37,REPLACE(AT38,1,1,"+")) -> MemeDef+VFEP_PirateMeme.symbolPacks.0.adjective
B38: =_xlfn.CONCAT($A38,REPLACE(B39,1,1,"+")) -> +VCF.ModDef+awnKindDef+awnsArrivalModeDef+receptDef+aidStrategyDef+ecipeDef+esearchProjectDef+esearchTabDef+itualBehaviorDef+itualOutcomeEffectDef+ulePackDef+cenarioDef+cenPartDef+tatDef+torytellerDef+hingDef+houghtDef+oolCapacityDef+raitDef+FECore.Abilities.AbilityDef+FECore.ExpandableProjectileDef+FECore.Misc.HireableFactionDef+FEPirates.CurseDef+FEPirates.WarcasketDef+orkGiverDef+orldObjectDef+eyed+ | C38: /VFEP_PirateMeme.description | D38: /VFEP_PirateMeme.descriptionMaker.rules.rulesStrings.0 | E38: /VFEP_PirateMeme.descriptionMaker.rules.rulesStrings.1 | F38: /VFEP_PirateMeme.descriptionMaker.rules.rulesStrings.10 | G38: /VFEP_PirateMeme.descriptionMaker.rules.rulesStrings.11 | H38: /VFEP_PirateMeme.descriptionMaker.rules.rulesStrings.12 | I38: /VFEP_PirateMeme.descriptionMaker.rules.rulesStrings.13 | J38: /VFEP_PirateMeme.descriptionMaker.rules.rulesStrings.14 | K38: /VFEP_PirateMeme.descriptionMaker.rules.rulesStrings.15 | L38: /VFEP_PirateMeme.descriptionMaker.rules.rulesStrings.16 | M38: /VFEP_PirateMeme.descriptionMaker.rules.rulesStrings.17 | N38: /VFEP_PirateMeme.descriptionMaker.rules.rulesStrings.18 | O38: /VFEP_PirateMeme.descriptionMaker.rules.rulesStrings.19 | P38: /VFEP_PirateMeme.descriptionMaker.rules.rulesStrings.2 | Q38: /VFEP_PirateMeme.descriptionMaker.rules.rulesStrings.20 | R38: /VFEP_PirateMeme.descriptionMaker.rules.rulesStrings.21 | S38: /VFEP_PirateMeme.descriptionMaker.rules.rulesStrings.22 | T38: /VFEP_PirateMeme.descriptionMaker.rules.rulesStrings.3 | U38: /VFEP_PirateMeme.descriptionMaker.rules.rulesStrings.4 | V38: /VFEP_PirateMeme.descriptionMaker.rules.rulesStrings.5 | W38: /VFEP_PirateMeme.descriptionMaker.rules.rulesStrings.6 | X38: /VFEP_PirateMeme.descriptionMaker.rules.rulesStrings.7 | Y38: /VFEP_PirateMeme.descriptionMaker.rules.rulesStrings.8 | Z38: /VFEP_PirateMeme.descriptionMaker.rules.rulesStrings.9 | AA38: /VFEP_PirateMeme.generalRules.rulesStrings.0 | AB38: /VFEP_PirateMeme.generalRules.rulesStrings.1 | AC38: /VFEP_PirateMeme.generalRules.rulesStrings.10 | AD38: /VFEP_PirateMeme.generalRules.rulesStrings.11 | AE38: /VFEP_PirateMeme.generalRules.rulesStrings.12 | AF38: /VFEP_PirateMeme.generalRules.rulesStrings.13 | AG38: /VFEP_PirateMeme.generalRules.rulesStrings.14 | AH38: /VFEP_PirateMeme.generalRules.rulesStrings.15 | AI38: /VFEP_PirateMeme.generalRules.rulesStrings.16 | AJ38: /VFEP_PirateMeme.generalRules.rulesStrings.17 | AK38: /VFEP_PirateMeme.generalRules.rulesStrings.2 | AL38: /VFEP_PirateMeme.generalRules.rulesStrings.3 | AM38: /VFEP_PirateMeme.generalRules.rulesStrings.4 | AN38: /VFEP_PirateMeme.generalRules.rulesStrings.5 | AO38: /VFEP_PirateMeme.generalRules.rulesStrings.6 | AP38: /VFEP_PirateMeme.generalRules.rulesStrings.7 | AQ38: /VFEP_PirateMeme.generalRules.rulesStrings.8 | AR38: /VFEP_PirateMeme.generalRules.rulesStrings.9 | AS38: /VFEP_PirateMeme.label | AT38: /VFEP_PirateMeme.symbolPacks.0.adjective
B39: =_xlfn.CONCAT($A39,REPLACE(B40,1,1,"+")) -> +VCF.ModDef+awnKindDef+awnsArrivalModeDef+receptDef+aidStrategyDef+ecipeDef+esearchProjectDef+esearchTabDef+itualBehaviorDef+itualOutcomeEffectDef+ulePackDef+cenarioDef+cenPartDef+tatDef+torytellerDef+hingDef+houghtDef+oolCapacityDef+raitDef+FECore.Abilities.AbilityDef+FECore.ExpandableProjectileDef+FECore.Misc.HireableFactionDef+FEPirates.CurseDef+FEPirates.WarcasketDef+orkGiverDef+orldObjectDef+eyed+ | C39: 강자는 약자의 것을 빼앗는 것이 당연한 권리이지만, 동지애와 규범은 그 무엇보다 우선시되어야 합니다. | D39: creation(tag=meme_Pirate) ->[deity0_name]은 약자들에게 [deity0_possessive]의지를 강요하기 위해서는 [memberNamePlural]가 함께 힘을 합쳐야 한다는 것을 보여주었습니다. | E39: episode(uses=1,tag=meme_Pirate) ->[deity0_name]은 모든[memberNamePlural]에게 "성실한 봉사에는 좁은 공유지, 낮은 임금, 고된 노동이 있고, 해적질에는 풍요와 포만감, 쾌락과 편안함, 자유와 권력이 있다.그것을 잡아라."라고 외쳤습니다. | F39: lessonReinforcement(tag=meme_Pirate) ->그는 전우애와 동지애, 그리고 서로를 존중하는 것의 장점을 소중히 여기도록 가르쳐주었습니다. | G39: archistBasis(tag=meme_Pirate) ->초월공학은 스스로를 방어할 수 없는 자를 존중하지 않습니다. 우리보다 약한 자들과 승무원으로서 맞설 것입니다. | H39: archistFact(tag=meme_Pirate) ->우리는 동지애와 동지애가 우리를 강하게 만드는 가치라는 것을 초월공학에 증명할 것입니다. | I39: archistProphecy(tag=meme_Pirate) ->함께 당당히 서야만 우리는 초월에 합당하게 될 수 있습니다. | J39: animistBasis(tag=meme_Pirate) ->영령은 스스로를 방어할 수 없는 자를 존중하지 않습니다. 우리는 승무원으로서 자신보다 약한 자들과 맞서 싸울 것입니다. | K39: animistFact(tag=meme_Pirate) ->우리는 전우애와 동지애가 우리를 강하게 만드는 가치라는 것을 영령들에게 증명할 것입니다. | L39: animistProphecy(tag=meme_Pirate) ->[itIsSaid] 함께 당당히 서야만 영혼들이 진정으로 우리의 말에 귀를 기울일 수 있습니다. | M39: serketistProphecy(tag=meme_Pirate)->[itIsSaid] 우리는 동지애와 동지애가 우리를 강하게 만드는 가치임을 증명할 것입니다. | N39: chthonianProphecy(tag=meme_Pirate)->이 사악한 존재들은 우리를 파괴하려 하지만 우리는 함께 맞서 싸울 것입니다. 우리의 동지애는 그 어떤 것도, 심지어 그들도 흔들 수 없습니다. | O39: esotericismProphecy(tag=meme_Pirate)->이러한 오컬트 지식에는 단합된 의지가 필요합니다. 우리는 동료애로 뭉쳐서 이 신비로운 비밀을 쉽게 받아들일 수 있을 것입니다. | P39: intro(tag=meme_Pirate) ->[place_summary][place_name]에 [memberNamePlural]이 안전한 피난처를 만들었는데, 그곳에서 그들의 약탈은 [deity0_name]의 영광으로 간주될 수 있었습니다.. | Q39: eschatologismFact(tag=meme_Pirate)->우리는 우리보다 약한 자들을 약탈하고 또 약탈할 것입니다. 그들이 만든 세상은 파괴되어야 하며, 오직 우리 선원들만이 그들의 업적을 누릴 자격이 있기 때문입니다. | R39: introMemo(tag=meme_Pirate)->재생 및 회수 사무소의 일원으로서, 지구상에서 발견되는 모든 자원은 회사의 자산이며, 따라서 회사의 자산을 소유하려는 적대적인 세력은 극도의 편견으로 종식시켜야 한다는 점을 상기시켜 드립니다. 우리는 정당한 우리의 것을 다른 사람이 가져가는 것을 허용하지 않을 것입니다. | S39: alienistProphecy(tag=meme_Pirate)->이 변덕스러운 생명체들은 우리가 마음대로 할 수 있는 우리의 것입니다. | T39: conflict(tag=meme_Pirate) ->겁쟁이 [foeLeader]는 경멸의 눈으로 이것을 보았습니다. [foeLeader_pronoun]는 [foeLeader_objective] 자신을 위한 모든 부를 원했습니다. | U39: founderJoin(tag=meme_Pirate) ->[deity0_name]의 가장 진실한 동반자인 선장 [founderName]이 [foeLeader]를 대담한 습격으로 붙잡았습니다. | V39: victory(tag=meme_Pirate) ->[founderName]의 승무원들은 [deity0_name]의 영광을 위해 [foeLeader]을 감금했고, 그는 며칠 후 처형당했습니다.. | W39: setup(tag=meme_Pirate) ->[founderName]은 위대한 선장이자 진정한 지도자였습니다. 수천 명의 해적들이 [founder_possessive]의 무시무시한 깃발 아래 뭉쳤습니다. | X39: story(uses=1,tag=meme_Pirate) ->[founderName]은 승무원으로서 고난과 고통, 희생을 함께 이겨내야 한다는 것을 깨닫게 해주었습니다. 우리는 동지애와 동료애를 소중히 여기고 서로를 존중하는 법을 배웠습니다. | Y39: lessonIntro(tag=meme_Pirate) ->역사상 가장 위대한 해적, 남자들 사이에서 전설로 통하는 해적과 이야기를 나눴습니다. 그는 저에게 보여주었습니다. | Z39: lesson(tag=meme_Pirate) ->승무원으로서 고난과 고통, 희생을 함께 감당해야 합니다. | AA39: memeAdjective->모험을 즐기는 | AB39: memeAdjective->범죄적인 | AC39: memeLeaderAdjective->가혹한 | AD39: memeLeaderAdjective->냉담한 | AE39: memeLeaderAdjective->용감한 | AF39: memeLeaderAdjective->무자비한 | AG39: memeLeaderAdjective->대담한 | AH39: memeMoralist->사제 | AI39: memeMoralist->일등 항해사 | AJ39: memeMoralist->일등 항해사 | AK39: memeAdjective->약탈하는 | AL39: memeAdjective->강탈하는 | AM39: memeAdjective->반항적인 | AN39: memeAdjective->해적의 | AO39: memeLeaderNoun->선장 | AP39: memeLeaderNoun->지휘관 | AQ39: memeLeaderNoun->두목 | AR39: memeLeaderAdjective->용맹한 | AS39: 해적 | AT39: 해적
A40: MVCF.ModDef | B40: =_xlfn.CONCAT($A40,REPLACE(B41,1,1,"+")) -> MVCF.ModDef+awnKindDef+awnsArrivalModeDef+receptDef+aidStrategyDef+ecipeDef+esearchProjectDef+esearchTabDef+itualBehaviorDef+itualOutcomeEffectDef+ulePackDef+cenarioDef+cenPartDef+tatDef+torytellerDef+hingDef+houghtDef+oolCapacityDef+raitDef+FECore.Abilities.AbilityDef+FECore.ExpandableProjectileDef+FECore.Misc.HireableFactionDef+FEPirates.CurseDef+FEPirates.WarcasketDef+orkGiverDef+orldObjectDef+eyed+ | C40: =_xlfn.CONCAT($A40,REPLACE(C41,1,1,"+")) -> MVCF.ModDef+VFEP.description | D40: =_xlfn.CONCAT($A40,REPLACE(D41,1,1,"+")) -> MVCF.ModDef+VFEP.label
...

Sheet Junker_First_Female
A1: Abigél
A2: Adrienn
A3: Alexandra
A4: Amália
A5: Amanda
A6: Amira
A7: Anett
A8: Angéla
A9: Angelika
A10: Annabella
A11: Aranka
A12: Barbara
... A130: Zorka

Sheet Junker_First_Male
A1: Adrián
A2: Aladár
A3: Alajos
A4: Albert
A5: Alfréd
A6: Ambrus
A7: András
A8: Arnold
A9: Balázs
A10: Bálint
A11: Barna
A12: Barnabás
... A80: Zétény

Sheet Junker_Last
A1: Great
A2: Tough
A3: Brutal
A4: Dangerous
A5: Savage
A6: Kind
A7: Fast
A8: Amazing
A9: Enormous
A10: Silly
A11: Dumb
A12: Marvelous
... A101: Zealous
